Workbook

Sheet Metadata
A1: Source: | B1: https://www.economy.com/products/tools/data-buffet
A2: Forecast Last Updated: | B2: 12/16/2024
A3: Last Historical Year: | B3: 12/31/23
A5: Moodys Sources
A6: Employment Sources: | B6: U.S. Bureau of Labor Statistics (BLS): Current Employment Statistics (CES); Quarterly Census of Employment and Wages (QCEW); Moody's Analytics Estimated
A7: GDP Sources: | B7: U.S. Bureau of Economic Analysis (BEA); Moody's Analytics Estimated and Forecasted

Sheet MoodysData(Raw)
A1: Mnemonic | B1: ForecastType | C1: MoodysSector | D1: CMAP Sector | E1: CleanDesc | F1: Geography | G1: Description | H1: 2005 | I1: 2006 | J1: 2007 | K1: 2008 | L1: 2009 | M1: 2010 | N1: 2011 | O1: 2012 | P1: 2013 | Q1: 2014 | R1: 2015 | S1: 2016 | T1: 2017 | U1: 2018 | V1: 2019 | W1: 2020 | X1: 2021 | Y1: 2022 | Z1: 2023 | AA1: 2024 | AB1: 2025 | AC1: 2026 | AD1: 2027 | AE1: 2028 | AF1: 2029 | AG1: 2030 | AH1: 2031 | AI1: 2032 | AJ1: 2033 | AK1: 2034 | AL1: 2035 | AM1: 2036 | AN1: 2037 | AO1: 2038 | AP1: 2039 | AQ1: 2040 | AR1: 2041 | AS1: 2042 | AT1: 2043 | AU1: 2044 | AV1: 2045 | AW1: 2046 | AX1: 2047 | AY1: 2048 | AZ1: 2049 | BA1: 2050 | BB1: 2051 | BC1: 2052 | BD1: 2053 | BE1: 2054 | BF1: 2055 | BG1: 2055
A2: RE211A.SS | B2: EMP | C2: 211 | D2: 211 | E2: Oil and gas extraction | F2: Sum of States | G2: Employment: Oil and gas extraction; (Ths. #; SA) | H2: 119.008 | I2: 127.109 | J2: 138.207 | K2: 151.321 | L2: 150.702 | M2: 153.544 | N2: 165.581 | O2: 180.237 | P2: 188.814 | Q2: 194.172 | R2: 185.319 | S2: 157.739 | T2: 144.256 | U2: 142.224 | V2: 140.935 | W2: 126.088 | X2: 113.3 | Y2: 114.512 | Z2: 119.048 | AA2: 120.299 | AB2: 121.38 | AC2: 120.109 | AD2: 117.783 | AE2: 115.236 | AF2: 112.965 | AG2: 110.722 | AH2: 109.056 | AI2: 107.658 | AJ2: 106.122 | AK2: 104.459 | AL2: 102.476 | AM2: 100.263 | AN2: 98.135 | AO2: 95.854 | AP2: 93.871 | AQ2: 91.898 | AR2: 89.83 | AS2: 87.725 | AT2: 85.472 | AU2: 83.119 | AV2: 80.626 | AW2: 77.977 | AX2: 75.169 | AY2: 72.593 | AZ2: 70.059 | BA2: 67.421 | BB2: 65.044 | BC2: 63.058 | BD2: 61.299 | BE2: 59.669 | BF2: 58.131 | BG2: 6.09
A3: RE212A.SS | B3: EMP | C3: 212 | D3: 212 | E3: Mining (except oil and gas) | F3: Sum of States | G3: Employment: Mining (except oil and gas); (Ths. #; SA) | H3: 214.623 | I3: 222.809 | J3: 223.972 | K3: 228.198 | L3: 210.451 | M3: 205.728 | N3: 216.763 | O3: 220.381 | P3: 212.273 | Q3: 207.991 | R3: 199.894 | S3: 181.886 | T3: 185.127 | U3: 190.617 | V3: 191.76 | W3: 176.795 | X3: 176.043 | Y3: 182.982 | Z3: 189.811 | AA3: 194.077 | AB3: 199.869 | AC3: 202.226 | AD3: 202.627 | AE3: 202.341 | AF3: 202.306 | AG3: 202.095 | AH3: 202.775 | AI3: 203.878 | AJ3: 204.511 | AK3: 204.672 | AL3: 203.933 | AM3: 202.461 | AN3: 200.845 | AO3: 198.606 | AP3: 196.739 | AQ3: 194.604 | AR3: 191.871 | AS3: 188.699 | AT3: 184.807 | AU3: 180.29 | AV3: 175.197 | AW3: 169.572 | AX3: 163.394 | AY3: 157.628 | AZ3: 151.848 | BA3: 145.708 | BB3: 140.087 | BC3: 135.293 | BD3: 130.943 | BE3: 126.814 | BF3: 122.827 | BG3: 2.3
A4: RE213A.SS | B4: EMP | C4: 213 | D4: 213 | E4: Support activities for mining | F4: Sum of States | G4: Employment: Support activities for mining; (Ths. #; SA) | H4: 224.703 | I4: 264.065 | J4: 297.356 | K4: 332.427 | L4: 277.736 | M4: 292.722 | N4: 349.797 | O4: 396.345 | P4: 410.059 | Q4: 445.442 | R4: 367.947 | S4: 265.041 | T4: 296.282 | U4: 341.424 | V4: 342.113 | W4: 238.357 | X4: 225.277 | Y4: 258.646 | Z4: 275.541 | AA4: 272.006 | AB4: 276.988 | AC4: 277.593 | AD4: 275.543 | AE4: 272.764 | AF4: 270.44 | AG4: 268.002 | AH4: 266.786 | AI4: 266.056 | AJ4: 264.821 | AK4: 263.105 | AL4: 260.395 | AM4: 256.915 | AN4: 253.464 | AO4: 249.434 | AP4: 245.999 | AQ4: 242.41 | AR4: 238.403 | AS4: 234.128 | AT4: 229.291 | AU4: 224.024 | AV4: 218.234 | AW4: 211.868 | AX4: 204.918 | AY4: 198.466 | AZ4: 192.008 | BA4: 185.154 | BB4: 178.919 | BC4: 173.666 | BD4: 168.955 | BE4: 164.518 | BF4: 160.259 | BG4: 1.44
A5: RE221A.SS | B5: EMP | C5: 221 | D5: 221 | E5: Utilities | F5: Sum of States | G5: Employment: Utilities; (Ths. #; SA) | H5: 548.775 | I5: 547.728 | J5: 551.139 | K5: 561.388 | L5: 563.321 | M5: 555.151 | N5: 553.217 | O5: 552.205 | P5: 551.768 | Q5: 551.544 | R5: 554.574 | S5: 554.783 | T5: 553.772 | U5: 552.452 | V5: 548.322 | W5: 545.226 | X5: 545.783 | Y5: 555.994 | Z5: 577.933 | AA5: 584.541 | AB5: 584.019 | AC5: 579.285 | AD5: 573.553 | AE5: 567.484 | AF5: 560.667 | AG5: 553.479 | AH5: 546.564 | AI5: 539.713 | AJ5: 533.064 | AK5: 526.541 | AL5: 520.118 | AM5: 513.505 | AN5: 506.548 | AO5: 499.855 | AP5: 493.549 | AQ5: 487.618 | AR5: 482.208 | AS5: 477.143 | AT5: 472.348 | AU5: 467.712 | AV5: 463.078 | AW5: 458.462 | AX5: 453.758 | AY5: 449.044 | AZ5: 444.426 | BA5: 439.902 | BB5: 435.477 | BC5: 431.096 | BD5: 426.756 | BE5: 422.269 | BF5: 417.705 | BG5: 8.13
A6: RE236A.SS | B6: EMP | C6: 236 | D6: 236 | E6: Construction of buildings | F6: Sum of States | G6: Employment: Construction of buildings; (Ths. #; SA) | H6: 1718.145 | I6: 1796.497 | J6: 1768.826 | K6: 1644.783 | L6: 1337.307 | M6: 1229.253 | N6: 1214.933 | O6: 1230.466 | P6: 1285.096 | Q6: 1352.741 | R6: 1429.37 | S6: 1494.512 | T6: 1547.065 | U6: 1619.735 | V6: 1664.632 | W6: 1600.826 | X6: 1662.316 | Y6: 1755.198 | Z6: 1806.741 | AA6: 1857.462 | AB6: 1894.58 | AC6: 1915.238 | AD6: 1915.047 | AE6: 1913.826 | AF6: 1907.396 | AG6: 1899.572 | AH6: 1893.233 | AI6: 1891.208 | AJ6: 1888.401 | AK6: 1886.785 | AL6: 1887.191 | AM6: 1889.541 | AN6: 1890.106 | AO6: 1888.534 | AP6: 1888.388 | AQ6: 1887.214 | AR6: 1885.649 | AS6: 1884.119 | AT6: 1883.018 | AU6: 1881.631 | AV6: 1879.35 | AW6: 1877.421 | AX6: 1874.752 | AY6: 1870.154 | AZ6: 1866.703 | BA6: 1866.396 | BB6: 1866.405 | BC6: 1865.688 | BD6: 1864.171 | BE6: 1860.962 | BF6: 1856.184 | BG6: 9.32
A7: RE237A.SS | B7: EMP | C7: 237 | D7: 237 | E7: Heavy and civil engineering construction | F7: Sum of States | G7: Employment: Heavy and civil engineering construction; (Ths. #; SA) | H7: 935.973 | I7: 979.337 | J7: 993.73 | K7: 962.881 | L7: 851.328 | M7: 814.088 | N7: 823.388 | O7: 853.94 | P7: 872.09 | Q7: 908.413 | R7: 939.883 | S7: 955.202 | T7: 988.995 | U7: 1033.301 | V7: 1073.493 | W7: 1039.69 | X7: 1041.767 | Y7: 1072.77 | Z7: 1108.17 | AA7: 1138.346 | AB7: 1146.117 | AC7: 1149.345 | AD7: 1140.198 | AE7: 1130.707 | AF7: 1118.524 | AG7: 1105.91 | AH7: 1094.552 | AI7: 1086.097 | AJ7: 1077.613 | AK7: 1070.232 | AL7: 1064.391 | AM7: 1059.998 | AN7: 1054.934 | AO7: 1049.007 | AP7: 1044.195 | AQ7: 1039.12 | AR7: 1034.146 | AS7: 1029.528 | AT7: 1025.49 | AU7: 1021.65 | AV7: 1017.683 | AW7: 1014.26 | AX7: 1010.798 | AY7: 1006.645 | AZ7: 1003.438 | BA7: 1002.247 | BB7: 1001.529 | BC7: 1000.725 | BD7: 999.837 | BE7: 998.366 | BF7: 996.366 | BG7: 14.63
A8: RE238A.SS | B8: EMP | C8: 238 | D8: 238 | E8: Specialty trade contractors | F8: Sum of States | G8: Employment: Specialty trade contractors; (Ths. #; SA) | H8: 4693.35 | I8: 4898.374 | J8: 4853.573 | K8: 4542.783 | L8: 3781.14 | M8: 3468.906 | N8: 3457.713 | O8: 3526.795 | P8: 3688.228 | Q8: 3876.895 | R8: 4088.122 | S8: 4277.279 | T8: 4421.381 | U8: 4602.208 | V8: 4742.101 | W8: 4592.538 | X8: 4745.549 | Y8: 4923.134 | Z8: 5049.39 | AA8: 5172.627 | AB8: 5274.476 | AC8: 5319.483 | AD8: 5306.607 | AE8: 5291.322 | AF8: 5262.295 | AG8: 5230.065 | AH8: 5202.481 | AI8: 5187.163 | AJ8: 5170.166 | AK8: 5156.851 | AL8: 5149.414 | AM8: 5147.632 | AN8: 5141.316 | AO8: 5129.586 | AP8: 5122.175 | AQ8: 5112.454 | AR8: 5102.159 | AS8: 5092.428 | AT8: 5084.317 | AU8: 5075.916 | AV8: 5065.52 | AW8: 5056.452 | AX8: 5045.767 | AY8: 5030.32 | AZ8: 5018.395 | BA8: 5015.348 | BB8: 5013.575 | BC8: 5010.261 | BD8: 5005.283 | BE8: 4996.178 | BF8: 4983.246 | BG8: 0.31
A9: RE311A.SS | B9: EMP | C9: 311 | D9: 311 | E9: Food manufacturing | F9: Sum of States | G9: Employment: Food manufacturing; (Ths. #; SA) | H9: 1477.529 | I9: 1470.57 | J9: 1474.868 | K9: 1472.485 | L9: 1450.236 | M9: 1445.597 | N9: 1458.376 | O9: 1462.76 | P9: 1472.038 | Q9: 1490.579 | R9: 1516.888 | S9: 1553.156 | T9: 1596.173 | U9: 1615.859 | V9: 1637.657 | W9: 1604.568 | X9: 1632.288 | Y9: 1693.85 | Z9: 1733.938 | AA9: 1763.38 | AB9: 1779.792 | AC9: 1793.993 | AD9: 1800.369 | AE9: 1800.112 | AF9: 1794.189 | AG9: 1785.039 | AH9: 1776.526 | AI9: 1768.335 | AJ9: 1760.024 | AK9: 1752.718 | AL9: 1745.654 | AM9: 1737.782 | AN9: 1728.481 | AO9: 1718.862 | AP9: 1710.031 | AQ9: 1701.358 | AR9: 1693.174 | AS9: 1685.023 | AT9: 1676.564 | AU9: 1667.62 | AV9: 1657.943 | AW9: 1648.009 | AX9: 1637.689 | AY9: 1627.004 | AZ9: 1616.961 | BA9: 1607.975 | BB9: 1600.374 | BC9: 1593.804 | BD9: 1587.888 | BE9: 1581.309 | BF9: 1573.943 | BG9: 0.02
A10: RE312A.SS | B10: EMP | C10: 312 | D10: 312 | E10: Beverage and tobacco product manufacturing | F10: Sum of States | G10: Employment: Beverage and tobacco product manufacturing; (Ths. #; SA) | H10: 193.94 | I10: 197.303 | J10: 199.036 | K10: 198.513 | L10: 190.266 | M10: 187.2 | N10: 187.938 | O10: 196.513 | P10: 204.127 | Q10: 215.01 | R10: 229.22 | S10: 248.611 | T10: 264.956 | U10: 276.828 | V10: 287.558 | W10: 274.255 | X10: 300.576 | Y10: 322.608 | Z10: 327.937 | AA10: 324.897 | AB10: 319.531 | AC10: 318.269 | AD10: 316.071 | AE10: 313.299 | AF10: 310.042 | AG10: 306.385 | AH10: 302.73 | AI10: 298.888 | AJ10: 294.98 | AK10: 290.74 | AL10: 286.247 | AM10: 281.455 | AN10: 276.458 | AO10: 271.427 | AP10: 266.312 | AQ10: 261.309 | AR10: 256.479 | AS10: 251.442 | AT10: 246.349 | AU10: 241.291 | AV10: 236.312 | AW10: 231.387 | AX10: 226.403 | AY10: 221.486 | AZ10: 216.736 | BA10: 212.155 | BB10: 207.769 | BC10: 203.528 | BD10: 199.397 | BE10: 195.234 | BF10: 191.062 | BG10: 0.03
A11: RE313A.SS | B11: EMP | C11: 313 | D11: 313 | E11: Textile mills | F11: Sum of States | G11: Employment: Textile mills; (Ths. #; SA) | H11: 216.619 | I11: 194.136 | J11: 171.057 | K11: 153.813 | L11: 126.285 | M11: 120.826 | N11: 119.973 | O11: 118.492 | P11: 117.06 | Q11: 116.482 | R11: 116.495 | S11: 114.345 | T11: 113.432 | U11: 111.733 | V11: 108.343 | W11: 95.4 | X11: 97.64 | Y11: 97.149 | Z11: 92.053 | AA11: 89.951 | AB11: 88.072 | AC11: 85.173 | AD11: 82.72 | AE11: 80.774 | AF11: 78.988 | AG11: 77.267 | AH11: 75.462 | AI11: 73.636 | AJ11: 71.964 | AK11: 70.303 | AL11: 68.736 | AM11: 67.197 | AN11: 65.693 | AO11: 64.258 | AP11: 62.899 | AQ11: 61.658 | AR11: 60.454 | AS11: 59.254 | AT11: 58.103 | AU11: 57.026 | AV11: 55.993 | AW11: 54.99 | AX11: 53.994 | AY11: 53.017 | AZ11: 52.069 | BA11: 51.149 | BB11: 50.24 | BC11: 49.34 | BD11: 48.45 | BE11: 47.544 | BF11: 46.635 | BG11: 2.44
A12: RE314A.SS | B12: EMP | C12: 314 | D12: 314 | E12: Textile product mills | F12: Sum of States | G12: Employment: Textile product mills; (Ths. #; SA) | H12: 171.282 | I12: 162.573 | J12: 157.297 | K12: 145.725 | L12: 123.915 | M12: 118.548 | N12: 117.147 | O12: 116.579 | P12: 114.201 | Q12: 114.873 | R12: 115.668 | S12: 116.28 | T12: 115.679 | U12: 116.238 | V12: 112.846 | W12: 101.143 | X12: 104.29 | Y12: 106.583 | Z12: 103.924 | AA12: 102.375 | AB12: 101.224 | AC12: 98.214 | AD12: 95.531 | AE12: 93.319 | AF12: 91.224 | AG12: 89.055 | AH12: 86.96 | AI12: 84.75 | AJ12: 82.512 | AK12: 80.394 | AL12: 78.276 | AM12: 76.22 | AN12: 74.2 | AO12: 72.249 | AP12: 70.346 | AQ12: 68.521 | AR12: 66.893 | AS12: 65.368 | AT12: 63.855 | AU12: 62.473 | AV12: 61.193 | AW12: 59.95 | AX12: 58.716 | AY12: 57.505 | AZ12: 56.325 | BA12: 55.172 | BB12: 54.034 | BC12: 52.909 | BD12: 51.797 | BE12: 50.676 | BF12: 49.556 | BG12: 2.75
A13: RE315A.SS | B13: EMP | C13: 315 | D13: 315 | E13: Apparel manufacturing | F13: Sum of States | G13: Employment: Apparel manufacturing; (Ths. #; SA) | H13: 251.463 | I13: 230.613 | J13: 210.239 | K13: 196.187 | L13: 164.914 | M13: 154.558 | N13: 148.514 | O13: 148.169 | P13: 142.972 | Q13: 139.199 | R13: 135.493 | S13: 129.883 | T13: 120.641 | U13: 113.614 | V13: 109.399 | W13: 89.185 | X13: 90.858 | Y13: 94.352 | Z13: 90.683 | AA13: 87.984 | AB13: 83.777 | AC13: 78.821 | AD13: 75.255 | AE13: 72.395 | AF13: 69.533 | AG13: 66.667 | AH13: 63.803 | AI13: 60.941 | AJ13: 58.1 | AK13: 55.37 | AL13: 52.817 | AM13: 50.41 | AN13: 48.135 | AO13: 45.982 | AP13: 43.971 | AQ13: 42.107 | AR13: 40.406 | AS13: 38.81 | AT13: 37.371 | AU13: 36.082 | AV13: 34.84 | AW13: 33.636 | AX13: 32.455 | AY13: 31.302 | AZ13: 30.187 | BA13: 29.114 | BB13: 28.07 | BC13: 27.059 | BD13: 26.074 | BE13: 25.105 | BF13: 24.16 | BG13: 0.21
... A85: RE813A.SS | B85: EMP | C85: 813 | D85: 813 | E85: Religious; grantmaking; civic; professional; and similar organizations | F85: Sum of States | G85: Employment: Religious; grantmaking; civic; professional; and similar organizations; (Ths. #; SA) | H85: 2556.295 | I85: 2569.533 | J85: 2599.302 | K85: 2640.179 | L85: 2607.156 | M85: 2572.615 | N85: 2569.909 | O85: 2602.293 | P85: 2623.626 | Q85: 2654.046 | R85: 2653.415 | S85: 2680.675 | T85: 2683.14 | U85: 2703.982 | V85: 2717.944 | W85: 2462.053 | X85: 2476.748 | Y85: 2578.014 | Z85: 2645.739 | AA85: 2708.167 | AB85: 2704.864 | AC85: 2667.275 | AD85: 2626.505 | AE85: 2588.015 | AF85: 2559.603 | AG85: 2537.356 | AH85: 2516.865 | AI85: 2498 | AJ85: 2479.261 | AK85: 2458.87 | AL85: 2440.556 | AM85: 2426.266 | AN85: 2411.31 | AO85: 2396.281 | AP85: 2383.537 | AQ85: 2372.516 | AR85: 2363.254 | AS85: 2355.387 | AT85: 2349.38 | AU85: 2344.968 | AV85: 2340.922 | AW85: 2337.292 | AX85: 2333.64 | AY85: 2330.725 | AZ85: 2330.097 | BA85: 2332.123 | BB85: 2335.781 | BC85: 2340.432 | BD85: 2345.396 | BE85: 2349.852 | BF85: 2354.242 | BG85: 8.65
A86: REFHA.SS | B86: EMP | C86: FH | D86: FH | E86: Fishing; hunting; etc. | F86: Sum of States | G86: Employment: Fishing; hunting; etc.; (Ths. #; SA) | H86: 402.546 | I86: 404.374 | J86: 404.201 | K86: 403.787 | L86: 382.995 | M86: 390.92 | N86: 397.592 | O86: 407.869 | P86: 418.03 | Q86: 427.067 | R86: 431.723 | S86: 438.659 | T86: 441.515 | U86: 448.555 | V86: 450.842 | W86: 434.914 | X86: 440.092 | Y86: 456.728 | Z86: 463.675 | AA86: 469.72 | AB86: 470.842 | AC86: 470.515 | AD86: 470.065 | AE86: 469.872 | AF86: 469.494 | AG86: 468.952 | AH86: 468.405 | AI86: 467.73 | AJ86: 467.069 | AK86: 466.374 | AL86: 465.724 | AM86: 465.017 | AN86: 464.277 | AO86: 463.527 | AP86: 462.864 | AQ86: 462.504 | AR86: 462.477 | AS86: 462.727 | AT86: 463.273 | AU86: 464.136 | AV86: 465.054 | AW86: 465.946 | AX86: 466.791 | AY86: 467.61 | AZ86: 468.443 | BA86: 469.265 | BB86: 470.079 | BC86: 470.867 | BD86: 471.595 | BE86: 472.256 | BF86: 472.868 | BG86: 2.61
A87: REFRA.SS | B87: EMP | C87: FR | D87: FR | E87: Farms | F87: Sum of States | G87: Employment: Farms; (Ths. #; SA) | H87: 2656.172 | I87: 2579.005 | J87: 2664.849 | K87: 2629.069 | L87: 2623.954 | M87: 2635.979 | N87: 2639.026 | O87: 2622.997 | P87: 2647.946 | Q87: 2649.015 | R87: 2650.989 | S87: 2644.024 | T87: 2622.027 | U87: 2617.031 | V87: 2586.065 | W87: 2577 | X87: 2573.015 | Y87: 2567.008 | Z87: 2591.817 | AA87: 2628.307 | AB87: 2637.999 | AC87: 2644.35 | AD87: 2648.498 | AE87: 2650.671 | AF87: 2650.374 | AG87: 2647.984 | AH87: 2642.651 | AI87: 2634.966 | AJ87: 2625.24 | AK87: 2613.976 | AL87: 2602.389 | AM87: 2591.535 | AN87: 2581.118 | AO87: 2571.105 | AP87: 2561.447 | AQ87: 2552.052 | AR87: 2542.554 | AS87: 2532.747 | AT87: 2522.611 | AU87: 2512.61 | AV87: 2502.909 | AW87: 2493.247 | AX87: 2483.797 | AY87: 2474.391 | AZ87: 2465.209 | BA87: 2456.154 | BB87: 2447.281 | BC87: 2438.991 | BD87: 2431.634 | BE87: 2425.165 | BF87: 2419.764 | BG87: 6.39
A88: REGVA.SS | B88: EMP | C88: GV | D88: 92 | E88: Government | F88: Sum of States | G88: Employment: Government; (Ths. #; SA) | H88: 21940.932 | I88: 22110.923 | J88: 22353.689 | K88: 22658.704 | L88: 22723.41 | M88: 22701.627 | N88: 22393.189 | O88: 22237.953 | P88: 22192.735 | Q88: 22249.517 | R88: 22372.911 | S88: 22563.882 | T88: 22689.03 | U88: 22796.375 | V88: 22934.575 | W88: 22240.183 | X88: 22126.025 | Y88: 22410.267 | Z88: 22947.158 | AA88: 23480.228 | AB88: 23715.309 | AC88: 23762.376 | AD88: 23803.395 | AE88: 23852.075 | AF88: 23941.247 | AG88: 24048.909 | AH88: 24143.965 | AI88: 24243.142 | AJ88: 24350.147 | AK88: 24432.322 | AL88: 24489.214 | AM88: 24554.173 | AN88: 24629.557 | AO88: 24719.587 | AP88: 24820.758 | AQ88: 24927.191 | AR88: 25034.024 | AS88: 25135.491 | AT88: 25233.297 | AU88: 25320.748 | AV88: 25402.565 | AW88: 25478.412 | AX88: 25555.814 | AY88: 25630.39 | AZ88: 25699.252 | BA88: 25765.561 | BB88: 25830.851 | BC88: 25897.183 | BD88: 25963.532 | BE88: 26026.478 | BF88: 26090.021 | BG88: 20.32
A89: REPHA.SS | B89: EMP | C89: PH | D89: 814 | E89: Private household workers | F89: Sum of States | G89: Employment: Private household workers; (Ths. #; SA) | H89: 184.31 | I89: 181.542 | J89: 187.252 | K89: 194.003 | L89: 198.611 | M89: 206.931 | N89: 211.918 | O89: 222.775 | P89: 223.934 | Q89: 230.401 | R89: 229.83 | S89: 229.821 | T89: 230.92 | U89: 234.706 | V89: 238.786 | W89: 217.891 | X89: 218.7 | Y89: 209.727 | Z89: 205.198 | AA89: 206.083 | AB89: 209.228 | AC89: 211.439 | AD89: 213.641 | AE89: 216.249 | AF89: 219.351 | AG89: 222.998 | AH89: 227.379 | AI89: 232.337 | AJ89: 237.784 | AK89: 243.623 | AL89: 249.707 | AM89: 255.543 | AN89: 261.069 | AO89: 266.458 | AP89: 271.757 | AQ89: 277.003 | AR89: 282.183 | AS89: 287.38 | AT89: 292.591 | AU89: 297.781 | AV89: 302.901 | AW89: 307.952 | AX89: 312.899 | AY89: 317.924 | AZ89: 322.976 | BA89: 328.114 | BB89: 333.328 | BC89: 338.463 | BD89: 343.323 | BE89: 347.861 | BF89: 352.01 | BG89: 10.71
A90: RGDP211$A.SS | B90: GDP | C90: 211 | D90: 211 | E90: Oil and gas extraction | F90: Sum of States | G90: Gross domestic product: Oil and gas extraction; (Mil. Ch. 2017 USD) | H90: 70909.046 | I90: 80549.445 | J90: 87161.442 | K90: 82501.73 | L90: 112049.78 | M90: 88668.056 | N90: 88874.419 | O90: 109586.3 | P90: 113768 | Q90: 126210.5 | R90: 171612.9 | S90: 178498.2 | T90: 161111.1 | U90: 151393.3 | V90: 191746.7 | W90: 210241 | X90: 163545.8 | Y90: 134027.3 | Z90: 208581.7 | AA90: 205929.87 | AB90: 196859.98 | AC90: 204628.27 | AD90: 210783.83 | AE90: 214862.64 | AF90: 219504.27 | AG90: 222711.24 | AH90: 223926.93 | AI90: 224311.41 | AJ90: 224460.27 | AK90: 224142.97 | AL90: 223558.86 | AM90: 222107.44 | AN90: 219518.71 | AO90: 216177.1 | AP90: 212130.79 | AQ90: 207498 | AR90: 202379.27 | AS90: 197013.71 | AT90: 191575.95 | AU90: 187335.78 | AV90: 183784.49 | AW90: 180503.46 | AX90: 177056.28 | AY90: 173611.97 | AZ90: 169938.87 | BA90: 166527.84 | BB90: 162905.54 | BC90: 159149.19 | BD90: 155338.28 | BE90: 151587.4 | BF90: 147886.61 | BG90: 6.46
A91: RGDP212$A.SS | B91: GDP | C91: 212 | D91: 212 | E91: Mining (except oil and gas) | F91: Sum of States | G91: Gross domestic product: Mining (except oil and gas); (Mil. Ch. 2017 USD) | H91: 68335.2 | I91: 70375.4 | J91: 72322.1 | K91: 66862.4 | L91: 62362.8 | M91: 64368.6 | N91: 64796.6 | O91: 57841.6 | P91: 58481.4 | Q91: 56695.6 | R91: 51918.9 | S91: 49775.6 | T91: 52266.4 | U91: 50723.5 | V91: 51130.3 | W91: 55290.7 | X91: 55123.3 | Y91: 53693.2 | Z91: 53432 | AA91: 53680.761 | AB91: 59002.988 | AC91: 60271.711 | AD91: 60868.598 | AE91: 61428.506 | AF91: 62363.008 | AG91: 62976.52 | AH91: 63148.699 | AI91: 62980.741 | AJ91: 62671.616 | AK91: 62172.684 | AL91: 61699.423 | AM91: 61190.149 | AN91: 60510.694 | AO91: 59568.524 | AP91: 58652.541 | AQ91: 57531.461 | AR91: 56393.583 | AS91: 55207.489 | AT91: 53980.661 | AU91: 52959.445 | AV91: 52138.333 | AW91: 51301.908 | AX91: 50507.504 | AY91: 49680.049 | AZ91: 48822.993 | BA91: 48005.725 | BB91: 47163.464 | BC91: 46333.878 | BD91: 45528.165 | BE91: 44740.628 | BF91: 43965.773 | BG91: 3.96
A92: RGDP213$A.SS | B92: GDP | C92: 213 | D92: 213 | E92: Support activities for mining | F92: Sum of States | G92: Gross domestic product: Support activities for mining; (Mil. Ch. 2017 USD) | H92: 33648.031 | I92: 49224.84 | J92: 56033.161 | K92: 62682.7 | L92: 46908.128 | M92: 52956.6 | N92: 66087.8 | O92: 69215.7 | P92: 74701.3 | Q92: 89938.6 | R92: 60700.7 | S92: 36478.3 | T92: 53926.025 | U92: 77476.2 | V92: 70867.3 | W92: 46907.5 | X92: 61025.7 | Y92: 80434.5 | Z92: 85550.9 | AA92: 85068.736 | AB92: 85961.906 | AC92: 82170.224 | AD92: 79965.489 | AE92: 80455.731 | AF92: 81437.299 | AG92: 83302.415 | AH92: 86336.034 | AI92: 90505.803 | AJ92: 94084.674 | AK92: 96640.47 | AL92: 98343.572 | AM92: 99389.74 | AN92: 100079.77 | AO92: 100350.65 | AP92: 100061.8 | AQ92: 99394.702 | AR92: 98620.192 | AS92: 97314.877 | AT92: 95459.903 | AU92: 93461.969 | AV92: 91635.55 | AW92: 89721.215 | AX92: 87553.762 | AY92: 85367.49 | AZ92: 83469.551 | BA92: 81549.566 | BB92: 79749.697 | BC92: 78300.171 | BD92: 77147.294 | BE92: 76089.459 | BF92: 75057.14 | BG92: 12.7
A93: RGDP221$A.SS | B93: GDP | C93: 221 | D93: 221 | E93: Utilities | F93: Sum of States | G93: Gross domestic product: Utilities; (Mil. Ch. 2017 USD) | H93: 239789.8 | I93: 254324.2 | J93: 260531 | K93: 276325.8 | L93: 256991.6 | M93: 290759.6 | N93: 301866.5 | O93: 306228.5 | P93: 304002.4 | Q93: 292728.5 | R93: 296933.4 | S93: 313557.4 | T93: 313710.2 | U93: 309271.3 | V93: 312518.4 | W93: 331357.3 | X93: 321278.7 | Y93: 326952.4 | Z93: 342977.2 | AA93: 342677.41 | AB93: 350840.1 | AC93: 357554.94 | AD93: 362471.47 | AE93: 365119.79 | AF93: 367566.82 | AG93: 370533.97 | AH93: 373525.63 | AI93: 376589.29 | AJ93: 379721.09 | AK93: 382752.27 | AL93: 385639.62 | AM93: 388649.84 | AN93: 391897.77 | AO93: 394755.27 | AP93: 397486.32 | AQ93: 399777.69 | AR93: 401942.74 | AS93: 404040.69 | AT93: 406166.1 | AU93: 408305.09 | AV93: 410444.87 | AW93: 411928.17 | AX93: 413480.62 | AY93: 415207.9 | AZ93: 416965.73 | BA93: 418790.33 | BB93: 420641.94 | BC93: 422519.14 | BD93: 424352.19 | BE93: 426125.18 | BF93: 427809.43 | BG93: 1.1
A94: RGDP236$A.SS | B94: GDP | C94: 236 | D94: 236 | E94: Construction of buildings | F94: Sum of States | G94: Gross domestic product: Construction of buildings; (Mil. Ch. 2017 USD) | H94: 245706.28 | I94: 240484.68 | J94: 228894.31 | K94: 202076.87 | L94: 168421.48 | M94: 158755.59 | N94: 154272.42 | O94: 158053.64 | P94: 164569.85 | Q94: 171284.82 | R94: 183589.45 | S94: 194981.5 | T94: 203996.19 | U94: 209800.79 | V94: 213466.91 | W94: 208880.16 | X94: 215957.77 | Y94: 208095.05 | Z94: 203255 | AA94: 213608.82 | AB94: 215451.72 | AC94: 221866.82 | AD94: 225976.7 | AE94: 229633.87 | AF94: 233768.94 | AG94: 237754.93 | AH94: 240357.4 | AI94: 243014.53 | AJ94: 245373.05 | AK94: 247353.19 | AL94: 249381.94 | AM94: 251574 | AN94: 253664.14 | AO94: 255660.27 | AP94: 257891.58 | AQ94: 259713.59 | AR94: 261191.08 | AS94: 262672.61 | AT94: 263924.8 | AU94: 265023.21 | AV94: 265926.03 | AW94: 266863.17 | AX94: 267936.55 | AY94: 268853.88 | AZ94: 269844.26 | BA94: 271271.11 | BB94: 272623.55 | BC94: 273776.94 | BD94: 274766.95 | BE94: 275733.43 | BF94: 276634.76 | BG94: 10.98
A95: RGDP237$A.SS | B95: GDP | C95: 237 | D95: 237 | E95: Heavy and civil engineering construction | F95: Sum of States | G95: Gross domestic product: Heavy and civil engineering construction; (Mil. Ch. 2017 USD) | H95: 140354.21 | I95: 137998.04 | J95: 137125.67 | K95: 128008.87 | L95: 116050.92 | M95: 115143.67 | N95: 116264.77 | O95: 122354.1 | P95: 125192.61 | Q95: 128697.04 | R95: 132999.75 | S95: 135290.1 | T95: 142714.5 | U95: 147801.79 | V95: 150983.73 | W95: 147588.32 | X95: 148042.6 | Y95: 136722.09 | Z95: 133818.17 | AA95: 139433.83 | AB95: 140440.67 | AC95: 145298.29 | AD95: 148655.54 | AE95: 151689.91 | AF95: 155019.42 | AG95: 158228.64 | AH95: 160501.18 | AI95: 162799.3 | AJ95: 164887.53 | AK95: 166710.15 | AL95: 168555.98 | AM95: 170502.21 | AN95: 172365.03 | AO95: 174145.3 | AP95: 176067.04 | AQ95: 177689.81 | AR95: 179057.61 | AS95: 180407.09 | AT95: 181577.73 | AU95: 182617.37 | AV95: 183498.32 | AW95: 184381.26 | AX95: 185337.74 | AY95: 186163.44 | AZ95: 187016.34 | BA95: 188147.81 | BB95: 189203.82 | BC95: 190098.13 | BD95: 190854.36 | BE95: 191569.74 | BF95: 192214.72 | BG95: 1.73
A96: RGDP238$A.SS | B96: GDP | C96: 238 | D96: 238 | E96: Specialty trade contractors | F96: Sum of States | G96: Gross domestic product: Specialty trade contractors; (Mil. Ch. 2017 USD) | H96: 547953.36 | I96: 534568.6 | J96: 522183.53 | K96: 471543.51 | L96: 402205.48 | M96: 382858.75 | N96: 378406.93 | O96: 389768.38 | P96: 407803.25 | Q96: 421238.03 | R96: 447818.02 | S96: 474086.78 | T96: 493509.22 | U96: 506152.42 | V96: 517836.35 | W96: 506209.61 | X96: 523607.54 | Y96: 495150.01 | Z96: 483988.03 | AA96: 506869.85 | AB96: 511693.5 | AC96: 527268.11 | AD96: 537370.98 | AE96: 546378.1 | AF96: 556498.64 | AG96: 566227.06 | AH96: 572648.19 | AI96: 579187.51 | AJ96: 584996.01 | AK96: 589886.51 | AL96: 594881.66 | AM96: 600254.58 | AN96: 605372.79 | AO96: 610251.34 | AP96: 615671.52 | AQ96: 620093.42 | AR96: 623669.85 | AS96: 627237.12 | AT96: 630235.43 | AU96: 632845 | AV96: 634963 | AW96: 637139.99 | AX96: 639617.77 | AY96: 641700.67 | AZ96: 643936.67 | BA96: 647193.52 | BB96: 650251.99 | BC96: 652813.93 | BD96: 654964.82 | BE96: 657037.37 | BF96: 658930.51 | BG96: 417.7
A97: RGDP311$A.SS | B97: GDP | C97: 311 | D97: 311 | E97: Food manufacturing | F97: Sum of States | G97: Gross domestic product: Food manufacturing; (Mil. Ch. 2017 USD) | H97: 140557.16 | I97: 156721.24 | J97: 162922.17 | K97: 152893.69 | L97: 156336.41 | M97: 155067.35 | N97: 155177.19 | O97: 151607.24 | P97: 163923.22 | Q97: 171700.36 | R97: 173444 | S97: 168195.38 | T97: 183716 | U97: 187422.14 | V97: 185139.07 | W97: 186339.55 | X97: 201607.07 | Y97: 208951 | Z97: 194833.12 | AA97: 189307.75 | AB97: 191877.74 | AC97: 193293.54 | AD97: 195031.72 | AE97: 197211.88 | AF97: 199495.32 | AG97: 201712.62 | AH97: 203852.59 | AI97: 206004.38 | AJ97: 208198.56 | AK97: 210373.75 | AL97: 212454.61 | AM97: 214514.92 | AN97: 216523.67 | AO97: 218350.07 | AP97: 220121.22 | AQ97: 221850.56 | AR97: 223536.55 | AS97: 225136.65 | AT97: 226642.87 | AU97: 228072.58 | AV97: 229435.3 | AW97: 230733.96 | AX97: 232083.18 | AY97: 233508.71 | AZ97: 234938.73 | BA97: 236342.18 | BB97: 237701.36 | BC97: 239092.08 | BD97: 240499.85 | BE97: 241887.87 | BF97: 243244.66 | BG97: 3.57
A98: RGDP312$A.SS | B98: GDP | C98: 312 | D98: 312 | E98: Beverage and tobacco product manufacturing | F98: Sum of States | G98: Gross domestic product: Beverage and tobacco product manufacturing; (Mil. Ch. 2017 USD) | H98: 96208.244 | I98: 105524.44 | J98: 104744.3 | K98: 101275.2 | L98: 106534.83 | M98: 95347.498 | N98: 87528.236 | O98: 87100.845 | P98: 87834.674 | Q98: 83081.607 | R98: 92939.088 | S98: 90697.64 | T98: 91548 | U98: 86652.299 | V98: 82126.769 | W98: 80425.432 | X98: 85302.662 | Y98: 85074.983 | Z98: 88633.112 | AA98: 90133.541 | AB98: 89699.465 | AC98: 88523.05 | AD98: 87520.543 | AE98: 86743.172 | AF98: 86033.204 | AG98: 85325.558 | AH98: 84609.506 | AI98: 83919.441 | AJ98: 83270.774 | AK98: 82638.032 | AL98: 81989.311 | AM98: 81350.58 | AN98: 80711.143 | AO98: 80025.006 | AP98: 79342.223 | AQ98: 78668.17 | AR98: 78000.478 | AS98: 77325.914 | AT98: 76641.841 | AU98: 75956.015 | AV98: 75272.681 | AW98: 74592.163 | AX98: 73948.731 | AY98: 73349.324 | AZ98: 72770.667 | BA98: 72206.562 | BB98: 71649.891 | BC98: 71121.757 | BD98: 70616.457 | BE98: 70121.959 | BF98: 69635.636 | BG98: 58.68
A99: RGDP313$A.SS | B99: GDP | C99: 313 | D99: 313 | E99: Textile mills | F99: Sum of States | G99: Gross domestic product: Textile mills; (Mil. Ch. 2017 USD) | H99: 13795.328 | I99: 12909.051 | J99: 12191.453 | K99: 11260.005 | L99: 8526.326 | M99: 8767.107 | N99: 7884.898 | O99: 8681.892 | P99: 9277.214 | Q99: 9654.036 | R99: 9324.193 | S99: 9239.972 | T99: 9031.127 | U99: 8533.779 | V99: 8291.751 | W99: 7721.95 | X99: 8196.766 | Y99: 7548.777 | Z99: 6980.854 | AA99: 7116.973 | AB99: 7185.328 | AC99: 7029.953 | AD99: 6974.275 | AE99: 7021.898 | AF99: 7087.476 | AG99: 7146.349 | AH99: 7184.718 | AI99: 7207.225 | AJ99: 7217.468 | AK99: 7208.92 | AL99: 7189.699 | AM99: 7177.832 | AN99: 7168.069 | AO99: 7155.197 | AP99: 7145.05 | AQ99: 7137.49 | AR99: 7130.22 | AS99: 7119.292 | AT99: 7103.741 | AU99: 7090.15 | AV99: 7081.516 | AW99: 7076.603 | AX99: 7076.951 | AY99: 7083.556 | AZ99: 7092.089 | BA99: 7101.641 | BB99: 7110.008 | BC99: 7122.881 | BD99: 7140.597 | BE99: 7159.939 | BF99: 7181.748 | BG99: 3.87
... A147: RGDP518$A.SS | B147: GDP | C147: 518 | D147: 518 | E147: Data processing; hosting and related services | F147: Sum of States | G147: Gross domestic product: Data processing; hosting and related services; (Mil. Ch. 2017 USD) | H147: 52469.93 | I147: 57502.398 | J147: 41940.697 | K147: 48914.463 | L147: 51900.5 | M147: 62775.595 | N147: 68707.938 | O147: 60105.013 | P147: 67039.034 | Q147: 74673.073 | R147: 76816.489 | S147: 88957.475 | T147: 96384.759 | U147: 112219.55 | V147: 137856.09 | W147: 162031.04 | X147: 199493.89 | Y147: 268013.86 | Z147: 309206.09 | AA147: 341604.18 | AB147: 350890.01 | AC147: 352183.44 | AD147: 354441.61 | AE147: 358571.81 | AF147: 363762.01 | AG147: 369686.19 | AH147: 375575.45 | AI147: 381846.11 | AJ147: 388229.66 | AK147: 393744.91 | AL147: 398358.3 | AM147: 403191.85 | AN147: 408310.63 | AO147: 413367.54 | AP147: 418831.3 | AQ147: 424626.76 | AR147: 430485.17 | AS147: 436410.29 | AT147: 442376.91 | AU147: 448408.61 | AV147: 454527.83 | AW147: 460757.64 | AX147: 467282.24 | AY147: 474293.6 | AZ147: 481693.86 | BA147: 489389.87 | BB147: 497331.2 | BC147: 505565.16 | BD147: 514052.21 | BE147: 522832.52 | BF147: 531957.79 | BG147: 27.93
A148: RGDP519$A.SS | B148: GDP | C148: 519 | D148: 519 | E148: Other information services | F148: Sum of States | G148: Gross domestic product: Other information services; (Mil. Ch. 2017 USD) | H148: 19170.976 | I148: 23055.158 | J148: 26604.439 | K148: 36835.59 | L148: 36113.657 | M148: 40969.742 | N148: 50134.967 | O148: 52033.988 | P148: 73380.062 | Q148: 81016.12 | R148: 96536.581 | S148: 107283.61 | T148: 117777.74 | U148: 125748.61 | V148: 151097.12 | W148: 173342.07 | X148: 202920.89 | Y148: 201350.62 | Z148: 235624.03 | AA148: 259947.71 | AB148: 269175.86 | AC148: 276750.61 | AD148: 285481.13 | AE148: 296028.84 | AF148: 307667.46 | AG148: 320100.58 | AH148: 332518.05 | AI148: 345343.01 | AJ148: 358286.54 | AK148: 370235.88 | AL148: 381097.89 | AM148: 392121.73 | AN148: 403362.02 | AO148: 414416.16 | AP148: 425836.24 | AQ148: 437530.37 | AR148: 449163.22 | AS148: 460739.34 | AT148: 472217.83 | AU148: 483636.14 | AV148: 495013.49 | AW148: 506367.72 | AX148: 517933.85 | AY148: 529971.97 | AZ148: 542364.85 | BA148: 554986.93 | BB148: 567764.27 | BC148: 580777.34 | BD148: 593975.23 | BE148: 607398.01 | BF148: 621117.42
A149: RGDP521$A.SS | B149: GDP | C149: 521 | D149: 521 | E149: Monetary authorities-central bank | F149: Sum of States | G149: Gross domestic product: Monetary authorities-central bank; (Mil. Ch. 2017 USD) | H149: 4693.118 | I149: 4649.329 | J149: 4536.654 | K149: 5745.632 | L149: 7922.323 | M149: 7357.008 | N149: 7463.898 | O149: 7429.002 | P149: 7118.018 | Q149: 7532.349 | R149: 7325.539 | S149: 7179.771 | T149: 6798.129 | U149: 6626.835 | V149: 6860.107 | W149: 6985.432 | X149: 7186.053 | Y149: 6937.03 | Z149: 7208.832 | AA149: 7758.671 | AB149: 7854.869 | AC149: 7902.047 | AD149: 7974.497 | AE149: 8025.582 | AF149: 8063.087 | AG149: 8103.134 | AH149: 8146.319 | AI149: 8194.258 | AJ149: 8244.394 | AK149: 8290.068 | AL149: 8328.576 | AM149: 8366.482 | AN149: 8408.224 | AO149: 8451.281 | AP149: 8498.213 | AQ149: 8546.569 | AR149: 8595.599 | AS149: 8648.064 | AT149: 8702.874 | AU149: 8759.196 | AV149: 8817.342 | AW149: 8877.564 | AX149: 8943.325 | AY149: 9016.379 | AZ149: 9093.388 | BA149: 9173.61 | BB149: 9257.788 | BC149: 9347.397 | BD149: 9440.541 | BE149: 9536.637 | BF149: 9638.815
A150: RGDP522$A.SS | B150: GDP | C150: 522 | D150: 522 | E150: Credit intermediation and related activities | F150: Sum of States | G150: Gross domestic product: Credit intermediation and related activities; (Mil. Ch. 2017 USD) | H150: 578301.16 | I150: 565953.13 | J150: 522332.51 | K150: 556991.5 | L150: 684067.51 | M150: 628784.84 | N150: 695724.04 | O150: 751465 | P150: 695552.4 | Q150: 716549.52 | R150: 707217.24 | S150: 675324 | T150: 642062.87 | U150: 616247.44 | V150: 644535.04 | W150: 691610.84 | X150: 726388.95 | Y150: 647094.19 | Z150: 631706.45 | AA150: 653075.84 | AB150: 654265.81 | AC150: 655918.46 | AD150: 659801.05 | AE150: 661969.49 | AF150: 663090.69 | AG150: 664499.93 | AH150: 666254.51 | AI150: 668488.63 | AJ150: 671003.9 | AK150: 673252.96 | AL150: 675008.05 | AM150: 676801.59 | AN150: 678998.14 | AO150: 681389.57 | AP150: 684197.47 | AQ150: 687222.43 | AR150: 690402.58 | AS150: 693963.53 | AT150: 697815.81 | AU150: 701892.82 | AV150: 706225.28 | AW150: 710831.61 | AX150: 715993.41 | AY150: 721855.08 | AZ150: 728148.79 | BA150: 734819.88 | BB150: 741928.56 | BC150: 749594.53 | BD150: 757666.07 | BE150: 766102.12 | BF150: 775146.74
A151: RGDP523$A.SS | B151: GDP | C151: 523 | D151: 523 | E151: Securities; commodity contracts; and other financial investments and related activities | F151: Sum of States | G151: Gross domestic product: Securities; commodity contracts; and other financial investments and related activities; (Mil. Ch. 2017 USD) | H151: 330529.6 | I151: 371303 | J151: 309853.8 | K151: 155032.2 | L151: 357766.1 | M151: 330344.3 | N151: 260767.7 | O151: 330864.7 | P151: 308939.1 | Q151: 248535.4 | R151: 245481.8 | S151: 274635.2 | T151: 283427.1 | U151: 273617.6 | V151: 257389.5 | W151: 264244.5 | X151: 266219.2 | Y151: 297382.3 | Z151: 312089.1 | AA151: 315923.24 | AB151: 317218.83 | AC151: 321037.85 | AD151: 325787.06 | AE151: 329604.78 | AF151: 332819.12 | AG151: 336146.36 | AH151: 339591.24 | AI151: 343200.22 | AJ151: 346852.84 | AK151: 350266.58 | AL151: 353324.91 | AM151: 356299.77 | AN151: 359388 | AO151: 362484.27 | AP151: 365691.03 | AQ151: 368900.97 | AR151: 372081.1 | AS151: 375349.03 | AT151: 378653.28 | AU151: 381953.28 | AV151: 385262.35 | AW151: 388590.77 | AX151: 392091.27 | AY151: 395838.8 | AZ151: 399683.68 | BA151: 403594.19 | BB151: 407600.76 | BC151: 411767.99 | BD151: 416010.95 | BE151: 420301.62 | BF151: 424766.16
A152: RGDP524$A.SS | B152: GDP | C152: 524 | D152: 524 | E152: Insurance carriers and related activities | F152: Sum of States | G152: Gross domestic product: Insurance carriers and related activities; (Mil. Ch. 2017 USD) | H152: 388472.5 | I152: 412216.4 | J152: 449852.1 | K152: 392533.3 | L152: 398782.4 | M152: 400160.2 | N152: 406082.9 | O152: 423533.8 | P152: 401416.7 | Q152: 500300.7 | R152: 566254.9 | S152: 581276 | T152: 568888.9 | U152: 575157.7 | V152: 614526.9 | W152: 588083.6 | X152: 607427.6 | Y152: 639271.6 | Z152: 632441.7 | AA152: 636134.21 | AB152: 655975.54 | AC152: 678423.64 | AD152: 703243.32 | AE152: 726239.23 | AF152: 748030.68 | AG152: 770044.36 | AH152: 792313.22 | AI152: 814971.24 | AJ152: 837777.48 | AK152: 860002.93 | AL152: 881264.85 | AM152: 902172.65 | AN152: 923168.59 | AO152: 943928.16 | AP152: 964735.25 | AQ152: 985267.67 | AR152: 1005394.5 | AS152: 1025409.4 | AT152: 1045147.2 | AU152: 1064462.5 | AV152: 1083359 | AW152: 1101823 | AX152: 1120254.5 | AY152: 1138840.7 | AZ152: 1157123.8 | BA152: 1174977.4 | BB152: 1192451.8 | BC152: 1209678.7 | BD152: 1226363.5 | BE152: 1242396.4 | BF152: 1258102.2
A153: RGDP525$A.SS | B153: GDP | C153: 525 | D153: 525 | E153: Funds; trusts; and other financial vehicles | F153: Sum of States | G153: Gross domestic product: Funds; trusts; and other financial vehicles; (Mil. Ch. 2017 USD) | H153: 7444.3 | I153: 7599.4 | J153: 5358.2 | K153: 2613.8 | L153: 430.3 | M153: 2994.2 | N153: 9784.6 | O153: 22994.8 | P153: 31516.2 | Q153: 68296 | R153: 33536.2 | S153: 4170.5 | T153: 6834 | U153: 646.817 | V153: 816.5 | W153: 631.714 | X153: 14374.3 | Y153: 5082.5 | Z153: 3458.3 | AA153: 3786.092 | AB153: 3697.223 | AC153: 3936.35 | AD153: 4196.005 | AE153: 4450.869 | AF153: 4703.945 | AG153: 4964.459 | AH153: 5232.099 | AI153: 5507.615 | AJ153: 5788.856 | AK153: 6070.275 | AL153: 6348.371 | AM153: 6626.628 | AN153: 6907.928 | AO153: 7189.466 | AP153: 7472.606 | AQ153: 7754.093 | AR153: 8032.188 | AS153: 8308.633 | AT153: 8581.38 | AU153: 8848.235 | AV153: 9108.547 | AW153: 9361.505 | AX153: 9610.045 | AY153: 9855.091 | AZ153: 10091.936 | BA153: 10318.755 | BB153: 10535.399 | BC153: 10742.527 | BD153: 10936.942 | BE153: 11117.066 | BF153: 11285.181
A154: RGDP531$A.SS | B154: GDP | C154: 531 | D154: 531 | E154: Real estate | F154: Sum of States | G154: Gross domestic product: Real estate; (Mil. Ch. 2017 USD) | H154: 1861345.4 | I154: 1860029.3 | J154: 2001945.2 | K154: 2075970.4 | L154: 2043189.2 | M154: 2142833.4 | N154: 2193392.4 | O154: 2219533.3 | P154: 2281109.9 | Q154: 2287535 | R154: 2265213.1 | S154: 2272322.4 | T154: 2312760 | U154: 2398011.4 | V154: 2424220.7 | W154: 2446912.3 | X154: 2592773.4 | Y154: 2762959.7 | Z154: 2816426.2 | AA154: 2863433.7 | AB154: 2926238.8 | AC154: 2984468.7 | AD154: 3052235.8 | AE154: 3123716.5 | AF154: 3195350.9 | AG154: 3267447.4 | AH154: 3340074.5 | AI154: 3414322.9 | AJ154: 3490028 | AK154: 3564931.8 | AL154: 3638423.4 | AM154: 3713006.8 | AN154: 3788180.9 | AO154: 3862015.9 | AP154: 3936662.6 | AQ154: 4012231.1 | AR154: 4088563.5 | AS154: 4165587.2 | AT154: 4243501.6 | AU154: 4321895.8 | AV154: 4400102.2 | AW154: 4478699.6 | AX154: 4559188.5 | AY154: 4642475.1 | AZ154: 4727392.6 | BA154: 4813470 | BB154: 4900890.3 | BC154: 4991077.3 | BD154: 5083399.2 | BE154: 5177670.5 | BF154: 5274691.3
A155: RGDP532$A.SS | B155: GDP | C155: 532 | D155: 532 | E155: Rental and leasing services | F155: Sum of States | G155: Gross domestic product: Rental and leasing services; (Mil. Ch. 2017 USD) | H155: 147524.15 | I155: 167540.07 | J155: 159820.42 | K155: 169263.92 | L155: 148783.39 | M155: 146597.55 | N155: 148897.76 | O155: 156563.16 | P155: 162338.73 | Q155: 166038.23 | R155: 179999.26 | S155: 191810.54 | T155: 194766.68 | U155: 207928.56 | V155: 220656.85 | W155: 221406.67 | X155: 241170.88 | Y155: 253047.6 | Z155: 271898.45 | AA155: 280705.2 | AB155: 289198.15 | AC155: 299364.54 | AD155: 310616.61 | AE155: 322363.41 | AF155: 334235.68 | AG155: 346248.37 | AH155: 358391.81 | AI155: 370782.34 | AJ155: 383407.46 | AK155: 396005.21 | AL155: 408484.88 | AM155: 421110.73 | AN155: 433805.33 | AO155: 446328.18 | AP155: 458914.68 | AQ155: 471562.39 | AR155: 484237.86 | AS155: 496918.73 | AT155: 509614.39 | AU155: 522257.46 | AV155: 534752.62 | AW155: 547152.76 | AX155: 559623.26 | AY155: 572261.3 | AZ155: 584909.08 | BA155: 597493.5 | BB155: 610017.02 | BC155: 622638.2 | BD155: 635261.76 | BE155: 647849.24 | BF155: 660484.91
A156: RGDP533$A.SS | B156: GDP | C156: 533 | D156: 533 | E156: Lessors of nonfinancial intangible assets (except copyrighted works) | F156: Sum of States | G156: Gross domestic product: Lessors of nonfinancial intangible assets (except copyrighted works); (Mil. Ch. 2017 USD) | H156: 14198.977 | I156: 17070.808 | J156: 16014.468 | K156: 16488.083 | L156: 15343.505 | M156: 14879.446 | N156: 13868.642 | O156: 14712.739 | P156: 14718.197 | Q156: 15014.87 | R156: 15398.734 | S156: 16775.858 | T156: 17491.216 | U156: 16860.344 | V156: 17584.15 | W156: 19711.627 | X156: 20077.116 | Y156: 20903.575 | Z156: 20873.802 | AA156: 21363.41 | AB156: 21734.188 | AC156: 22021.969 | AD156: 22376.059 | AE156: 22760.125 | AF156: 23146.717 | AG156: 23537.642 | AH156: 23932.238 | AI156: 24338.358 | AJ156: 24755.24 | AK156: 25167.038 | AL156: 25569.816 | AM156: 25981.804 | AN156: 26399.02 | AO156: 26808.425 | AP156: 27224.987 | AQ156: 27649.861 | AR156: 28082.312 | AS156: 28521.655 | AT156: 28969.674 | AU156: 29423.877 | AV156: 29879.944 | AW156: 30342.254 | AX156: 30820.893 | AY156: 31322.157 | AZ156: 31838.463 | BA156: 32367.005 | BB156: 32909.052 | BC156: 33474.665 | BD156: 34060.122 | BE156: 34664.393 | BF156: 35293.181
A157: RGDP541$A.SS | B157: GDP | C157: 541 | D157: 541 | E157: Professional; scientific; and technical services | F157: Sum of States | G157: Gross domestic product: Professional; scientific; and technical services; (Mil. Ch. 2017 USD) | H157: 1004832.6 | I157: 1044199 | J157: 1086301 | K157: 1172965.4 | L157: 1107412.6 | M157: 1138354.9 | N157: 1190012.5 | O157: 1243679.3 | P157: 1254106.9 | Q157: 1306549.6 | R157: 1365708.8 | S157: 1408373.7 | T157: 1460642.1 | U157: 1558185.1 | V157: 1644065.6 | W157: 1656742.6 | X157: 1882036.7 | Y157: 2034392.3 | Z157: 2117303 | AA157: 2200106.9 | AB157: 2278758.4 | AC157: 2353144.2 | AD157: 2434657.3 | AE157: 2522523.2 | AF157: 2613056.9 | AG157: 2705542.3 | AH157: 2797116.3 | AI157: 2891375.2 | AJ157: 2987968.6 | AK157: 3082065 | AL157: 3174033.4 | AM157: 3269943.1 | AN157: 3368731.4 | AO157: 3467336.9 | AP157: 3568562.9 | AQ157: 3672066.2 | AR157: 3776620.4 | AS157: 3882347.4 | AT157: 3989394.5 | AU157: 4098210.8 | AV157: 4208469.7 | AW157: 4319811.8 | AX157: 4434209.1 | AY157: 4553045.9 | AZ157: 4674941.9 | BA157: 4799871.4 | BB157: 4927320.1 | BC157: 5058700.4 | BD157: 5193562.2 | BE157: 5332289.9 | BF157: 5475745.5
A158: RGDP551$A.SS | B158: GDP | C158: 551 | D158: 551 | E158: Management of companies and enterprises | F158: Sum of States | G158: Gross domestic product: Management of companies and enterprises; (Mil. Ch. 2017 USD) | H158: 270157.2 | I158: 269741.9 | J158: 264413.4 | K158: 265969.7 | L158: 243303.1 | M158: 262317.2 | N158: 273275.5 | O158: 294769.8 | P158: 310441.8 | Q158: 331086.9 | R158: 340541.9 | S158: 345553.7 | T158: 370133.7 | U158: 394968.1 | V158: 421632.7 | W158: 430136.2 | X158: 477038.9 | Y158: 528002.3 | Z158: 536474.6 | AA158: 550865.45 | AB158: 562781.84 | AC158: 572379.41 | AD158: 581798.7 | AE158: 592235.37 | AF158: 603505.47 | AG158: 615520.7 | AH158: 627527.43 | AI158: 639882.98 | AJ158: 652563.29 | AK158: 664714.12 | AL158: 676518.27 | AM158: 688977.52 | AN158: 701753.13 | AO158: 714299.91 | AP158: 726933.44 | AQ158: 739394.42 | AR158: 751702.07 | AS158: 764040.57 | AT158: 776393.61 | AU158: 788812.21 | AV158: 801294.82 | AW158: 813730.03 | AX158: 826381.89 | AY158: 839455.42 | AZ158: 852682.26 | BA158: 865917.56 | BB158: 879134.05 | BC158: 892596.19 | BD158: 906243.43 | BE158: 920141.98 | BF158: 934378.66
...

Sheet Implied Productivity Ratios
F1: Units
E2: EMP | F2: Thousands
E3: GDP | F3: Millions | G3: (chained 2017)
E4: Ratio: | F4: Thousands GDP / worker | BD4: Extrapolated
C5: CMAP Sector | D5: CleanDesc | E5: 2005 | F5: 2006 | G5: 2007 | H5: 2008 | I5: 2009 | J5: 2010 | K5: 2011 | L5: 2012 | M5: 2013 | N5: 2014 | O5: 2015 | P5: 2016 | Q5: 2017 | R5: 2018 | S5: 2019 | T5: 2020 | U5: 2021 | V5: 2022 | W5: 2023 | X5: 2024 | Y5: 2025 | Z5: 2026 | AA5: 2027 | AB5: 2028 | AC5: 2029 | AD5: 2030 | AE5: 2031 | AF5: 2032 | AG5: 2033 | AH5: 2034 | AI5: 2035 | AJ5: 2036 | AK5: 2037 | AL5: 2038 | AM5: 2039 | AN5: 2040 | AO5: 2041 | AP5: 2042 | AQ5: 2043 | AR5: 2044 | AS5: 2045 | AT5: 2046 | AU5: 2047 | AV5: 2048 | AW5: 2049 | AX5: 2050 | AY5: 2051 | AZ5: 2052 | BA5: 2053 | BB5: 2054 | BC5: 2055 | BD5: 2056 | BE5: 2057 | BF5: 2058 | BG5: 2059 | BH5: 2060
C6: 211 | D6: Oil and gas extraction | E6: =SUMIFS('MoodysData(Raw)'!H$2:H$180,'MoodysData(Raw)'!$B$2:$B$180,"=GDP",'MoodysData(Raw)'!$D$2:$D$180,"="&'Implied Productivity Ratios'!$C6)/SUMIFS('MoodysData(Raw)'!H$2:H$180,'MoodysData(Raw)'!$B$2:$B$180,"=EMP",'MoodysData(Raw)'!$D$2:$D$180,"="&'Implied Productivity Ratios'!$C6) -> 595.83428 | F6: =SUMIFS('MoodysData(Raw)'!I$2:I$180,'MoodysData(Raw)'!$B$2:$B$180,"=GDP",'MoodysData(Raw)'!$D$2:$D$180,"="&'Implied Productivity Ratios'!$C6)/SUMIFS('MoodysData(Raw)'!I$2:I$180,'MoodysData(Raw)'!$B$2:$B$180,"=EMP",'MoodysData(Raw)'!$D$2:$D$180,"="&'Implied Productivity Ratios'!$C6) -> 633.70371 | G6: =SUMIFS('MoodysData(Raw)'!J$2:J$180,'MoodysData(Raw)'!$B$2:$B$180,"=GDP",'MoodysData(Raw)'!$D$2:$D$180,"="&'Implied Productivity Ratios'!$C6)/SUMIFS('MoodysData(Raw)'!J$2:J$180,'MoodysData(Raw)'!$B$2:$B$180,"=EMP",'MoodysData(Raw)'!$D$2:$D$180,"="&'Implied Productivity Ratios'!$C6) -> 630.65866 | H6: =SUMIFS('MoodysData(Raw)'!K$2:K$180,'MoodysData(Raw)'!$B$2:$B$180,"=GDP",'MoodysData(Raw)'!$D$2:$D$180,"="&'Implied Productivity Ratios'!$C6)/SUMIFS('MoodysData(Raw)'!K$2:K$180,'MoodysData(Raw)'!$B$2:$B$180,"=EMP",'MoodysData(Raw)'!$D$2:$D$180,"="&'Implied Productivity Ratios'!$C6) -> 545.21005 | I6: =SUMIFS('MoodysData(Raw)'!L$2:L$180,'MoodysData(Raw)'!$B$2:$B$180,"=GDP",'MoodysData(Raw)'!$D$2:$D$180,"="&'Implied Productivity Ratios'!$C6)/SUMIFS('MoodysData(Raw)'!L$2:L$180,'MoodysData(Raw)'!$B$2:$B$180,"=EMP",'MoodysData(Raw)'!$D$2:$D$180,"="&'Implied Productivity Ratios'!$C6) -> 743.51887 | J6: =SUMIFS('MoodysData(Raw)'!M$2:M$180,'MoodysData(Raw)'!$B$2:$B$180,"=GDP",'MoodysData(Raw)'!$D$2:$D$180,"="&'Implied Productivity Ratios'!$C6)/SUMIFS('MoodysData(Raw)'!M$2:M$180,'MoodysData(Raw)'!$B$2:$B$180,"=EMP",'MoodysData(Raw)'!$D$2:$D$180,"="&'Implied Productivity Ratios'!$C6) -> 577.47653 | K6: =SUMIFS('MoodysData(Raw)'!N$2:N$180,'MoodysData(Raw)'!$B$2:$B$180,"=GDP",'MoodysData(Raw)'!$D$2:$D$180,"="&'Implied Productivity Ratios'!$C6)/SUMIFS('MoodysData(Raw)'!N$2:N$180,'MoodysData(Raw)'!$B$2:$B$180,"=EMP",'MoodysData(Raw)'!$D$2:$D$180,"="&'Implied Productivity Ratios'!$C6) -> 536.74286 | L6: =SUMIFS('MoodysData(Raw)'!O$2:O$180,'MoodysData(Raw)'!$B$2:$B$180,"=GDP",'MoodysData(Raw)'!$D$2:$D$180,"="&'Implied Productivity Ratios'!$C6)/SUMIFS('MoodysData(Raw)'!O$2:O$180,'MoodysData(Raw)'!$B$2:$B$180,"=EMP",'MoodysData(Raw)'!$D$2:$D$180,"="&'Implied Productivity Ratios'!$C6) -> 608.01223 | ... BC6: =SUMIFS('MoodysData(Raw)'!BF$2:BF$180,'MoodysData(Raw)'!$B$2:$B$180,"=GDP",'MoodysData(Raw)'!$D$2:$D$180,"="&'Implied Productivity Ratios'!$C6)/SUMIFS('MoodysData(Raw)'!BF$2:BF$180,'MoodysData(Raw)'!$B$2:$B$180,"=EMP",'MoodysData(Raw)'!$D$2:$D$180,"="&'Implied Productivity Ratios'!$C6) -> 2544.0231 | BD6: =BC6+($BC6-$AX6)/5 -> 2558.8337 | BE6: =BD6+($BC6-$AX6)/5 -> 2573.6443 | BF6: =BE6+($BC6-$AX6)/5 -> 2588.4549 | BG6: =BF6+($BC6-$AX6)/5 -> 2603.2656 | BH6: =BG6+($BC6-$AX6)/5 -> 2618.0762
C7: 212 | D7: Mining (except oil and gas) | E7: =SUMIFS('MoodysData(Raw)'!H$2:H$180,'MoodysData(Raw)'!$B$2:$B$180,"=GDP",'MoodysData(Raw)'!$D$2:$D$180,"="&'Implied Productivity Ratios'!$C7)/SUMIFS('MoodysData(Raw)'!H$2:H$180,'MoodysData(Raw)'!$B$2:$B$180,"=EMP",'MoodysData(Raw)'!$D$2:$D$180,"="&'Implied Productivity Ratios'!$C7) -> 318.39644 | F7: =SUMIFS('MoodysData(Raw)'!I$2:I$180,'MoodysData(Raw)'!$B$2:$B$180,"=GDP",'MoodysData(Raw)'!$D$2:$D$180,"="&'Implied Productivity Ratios'!$C7)/SUMIFS('MoodysData(Raw)'!I$2:I$180,'MoodysData(Raw)'!$B$2:$B$180,"=EMP",'MoodysData(Raw)'!$D$2:$D$180,"="&'Implied Productivity Ratios'!$C7) -> 315.85528 | G7: =SUMIFS('MoodysData(Raw)'!J$2:J$180,'MoodysData(Raw)'!$B$2:$B$180,"=GDP",'MoodysData(Raw)'!$D$2:$D$180,"="&'Implied Productivity Ratios'!$C7)/SUMIFS('MoodysData(Raw)'!J$2:J$180,'MoodysData(Raw)'!$B$2:$B$180,"=EMP",'MoodysData(Raw)'!$D$2:$D$180,"="&'Implied Productivity Ratios'!$C7) -> 322.90688 | H7: =SUMIFS('MoodysData(Raw)'!K$2:K$180,'MoodysData(Raw)'!$B$2:$B$180,"=GDP",'MoodysData(Raw)'!$D$2:$D$180,"="&'Implied Productivity Ratios'!$C7)/SUMIFS('MoodysData(Raw)'!K$2:K$180,'MoodysData(Raw)'!$B$2:$B$180,"=EMP",'MoodysData(Raw)'!$D$2:$D$180,"="&'Implied Productivity Ratios'!$C7) -> 293.00169 | I7: =SUMIFS('MoodysData(Raw)'!L$2:L$180,'MoodysData(Raw)'!$B$2:$B$180,"=GDP",'MoodysData(Raw)'!$D$2:$D$180,"="&'Implied Productivity Ratios'!$C7)/SUMIFS('MoodysData(Raw)'!L$2:L$180,'MoodysData(Raw)'!$B$2:$B$180,"=EMP",'MoodysData(Raw)'!$D$2:$D$180,"="&'Implied Productivity Ratios'!$C7) -> 296.32931 | J7: =SUMIFS('MoodysData(Raw)'!M$2:M$180,'MoodysData(Raw)'!$B$2:$B$180,"=GDP",'MoodysData(Raw)'!$D$2:$D$180,"="&'Implied Productivity Ratios'!$C7)/SUMIFS('MoodysData(Raw)'!M$2:M$180,'MoodysData(Raw)'!$B$2:$B$180,"=EMP",'MoodysData(Raw)'!$D$2:$D$180,"="&'Implied Productivity Ratios'!$C7) -> 312.88206 | K7: =SUMIFS('MoodysData(Raw)'!N$2:N$180,'MoodysData(Raw)'!$B$2:$B$180,"=GDP",'MoodysData(Raw)'!$D$2:$D$180,"="&'Implied Productivity Ratios'!$C7)/SUMIFS('MoodysData(Raw)'!N$2:N$180,'MoodysData(Raw)'!$B$2:$B$180,"=EMP",'MoodysData(Raw)'!$D$2:$D$180,"="&'Implied Productivity Ratios'!$C7) -> 298.92832 | L7: =SUMIFS('MoodysData(Raw)'!O$2:O$180,'MoodysData(Raw)'!$B$2:$B$180,"=GDP",'MoodysData(Raw)'!$D$2:$D$180,"="&'Implied Productivity Ratios'!$C7)/SUMIFS('MoodysData(Raw)'!O$2:O$180,'MoodysData(Raw)'!$B$2:$B$180,"=EMP",'MoodysData(Raw)'!$D$2:$D$180,"="&'Implied Productivity Ratios'!$C7) -> 262.46183 | ... BC7: =SUMIFS('MoodysData(Raw)'!BF$2:BF$180,'MoodysData(Raw)'!$B$2:$B$180,"=GDP",'MoodysData(Raw)'!$D$2:$D$180,"="&'Implied Productivity Ratios'!$C7)/SUMIFS('MoodysData(Raw)'!BF$2:BF$180,'MoodysData(Raw)'!$B$2:$B$180,"=EMP",'MoodysData(Raw)'!$D$2:$D$180,"="&'Implied Productivity Ratios'!$C7) -> 357.94877 | BD7: =BC7+($BC7-$AX7)/5 -> 363.64547 | BE7: =BD7+($BC7-$AX7)/5 -> 369.34217 | BF7: =BE7+($BC7-$AX7)/5 -> 375.03886 | BG7: =BF7+($BC7-$AX7)/5 -> 380.73556 | BH7: =BG7+($BC7-$AX7)/5 -> 386.43226
C8: 213 | D8: Support activities for mining | E8: =SUMIFS('MoodysData(Raw)'!H$2:H$180,'MoodysData(Raw)'!$B$2:$B$180,"=GDP",'MoodysData(Raw)'!$D$2:$D$180,"="&'Implied Productivity Ratios'!$C8)/SUMIFS('MoodysData(Raw)'!H$2:H$180,'MoodysData(Raw)'!$B$2:$B$180,"=EMP",'MoodysData(Raw)'!$D$2:$D$180,"="&'Implied Productivity Ratios'!$C8) -> 149.74447 | F8: =SUMIFS('MoodysData(Raw)'!I$2:I$180,'MoodysData(Raw)'!$B$2:$B$180,"=GDP",'MoodysData(Raw)'!$D$2:$D$180,"="&'Implied Productivity Ratios'!$C8)/SUMIFS('MoodysData(Raw)'!I$2:I$180,'MoodysData(Raw)'!$B$2:$B$180,"=EMP",'MoodysData(Raw)'!$D$2:$D$180,"="&'Implied Productivity Ratios'!$C8) -> 186.41183 | G8: =SUMIFS('MoodysData(Raw)'!J$2:J$180,'MoodysData(Raw)'!$B$2:$B$180,"=GDP",'MoodysData(Raw)'!$D$2:$D$180,"="&'Implied Productivity Ratios'!$C8)/SUMIFS('MoodysData(Raw)'!J$2:J$180,'MoodysData(Raw)'!$B$2:$B$180,"=EMP",'MoodysData(Raw)'!$D$2:$D$180,"="&'Implied Productivity Ratios'!$C8) -> 188.43797 | H8: =SUMIFS('MoodysData(Raw)'!K$2:K$180,'MoodysData(Raw)'!$B$2:$B$180,"=GDP",'MoodysData(Raw)'!$D$2:$D$180,"="&'Implied Productivity Ratios'!$C8)/SUMIFS('MoodysData(Raw)'!K$2:K$180,'MoodysData(Raw)'!$B$2:$B$180,"=EMP",'MoodysData(Raw)'!$D$2:$D$180,"="&'Implied Productivity Ratios'!$C8) -> 188.5608 | I8: =SUMIFS('MoodysData(Raw)'!L$2:L$180,'MoodysData(Raw)'!$B$2:$B$180,"=GDP",'MoodysData(Raw)'!$D$2:$D$180,"="&'Implied Productivity Ratios'!$C8)/SUMIFS('MoodysData(Raw)'!L$2:L$180,'MoodysData(Raw)'!$B$2:$B$180,"=EMP",'MoodysData(Raw)'!$D$2:$D$180,"="&'Implied Productivity Ratios'!$C8) -> 168.89466 | J8: =SUMIFS('MoodysData(Raw)'!M$2:M$180,'MoodysData(Raw)'!$B$2:$B$180,"=GDP",'MoodysData(Raw)'!$D$2:$D$180,"="&'Implied Productivity Ratios'!$C8)/SUMIFS('MoodysData(Raw)'!M$2:M$180,'MoodysData(Raw)'!$B$2:$B$180,"=EMP",'MoodysData(Raw)'!$D$2:$D$180,"="&'Implied Productivity Ratios'!$C8) -> 180.9109 | K8: =SUMIFS('MoodysData(Raw)'!N$2:N$180,'MoodysData(Raw)'!$B$2:$B$180,"=GDP",'MoodysData(Raw)'!$D$2:$D$180,"="&'Implied Productivity Ratios'!$C8)/SUMIFS('MoodysData(Raw)'!N$2:N$180,'MoodysData(Raw)'!$B$2:$B$180,"=EMP",'MoodysData(Raw)'!$D$2:$D$180,"="&'Implied Productivity Ratios'!$C8) -> 188.93187 | L8: =SUMIFS('MoodysData(Raw)'!O$2:O$180,'MoodysData(Raw)'!$B$2:$B$180,"=GDP",'MoodysData(Raw)'!$D$2:$D$180,"="&'Implied Productivity Ratios'!$C8)/SUMIFS('MoodysData(Raw)'!O$2:O$180,'MoodysData(Raw)'!$B$2:$B$180,"=EMP",'MoodysData(Raw)'!$D$2:$D$180,"="&'Implied Productivity Ratios'!$C8) -> 174.63498 | ... BC8: =SUMIFS('MoodysData(Raw)'!BF$2:BF$180,'MoodysData(Raw)'!$B$2:$B$180,"=GDP",'MoodysData(Raw)'!$D$2:$D$180,"="&'Implied Productivity Ratios'!$C8)/SUMIFS('MoodysData(Raw)'!BF$2:BF$180,'MoodysData(Raw)'!$B$2:$B$180,"=EMP",'MoodysData(Raw)'!$D$2:$D$180,"="&'Implied Productivity Ratios'!$C8) -> 468.34899 | BD8: =BC8+($BC8-$AX8)/5 -> 473.93042 | BE8: =BD8+($BC8-$AX8)/5 -> 479.51185 | BF8: =BE8+($BC8-$AX8)/5 -> 485.09328 | BG8: =BF8+($BC8-$AX8)/5 -> 490.67471 | BH8: =BG8+($BC8-$AX8)/5 -> 496.25614
C9: 221 | D9: Utilities | E9: =SUMIFS('MoodysData(Raw)'!H$2:H$180,'MoodysData(Raw)'!$B$2:$B$180,"=GDP",'MoodysData(Raw)'!$D$2:$D$180,"="&'Implied Productivity Ratios'!$C9)/SUMIFS('MoodysData(Raw)'!H$2:H$180,'MoodysData(Raw)'!$B$2:$B$180,"=EMP",'MoodysData(Raw)'!$D$2:$D$180,"="&'Implied Productivity Ratios'!$C9) -> 873.90934 | F9: =SUMIFS('MoodysData(Raw)'!I$2:I$180,'MoodysData(Raw)'!$B$2:$B$180,"=GDP",'MoodysData(Raw)'!$D$2:$D$180,"="&'Implied Productivity Ratios'!$C9)/SUMIFS('MoodysData(Raw)'!I$2:I$180,'MoodysData(Raw)'!$B$2:$B$180,"=EMP",'MoodysData(Raw)'!$D$2:$D$180,"="&'Implied Productivity Ratios'!$C9) -> 928.65145 | G9: =SUMIFS('MoodysData(Raw)'!J$2:J$180,'MoodysData(Raw)'!$B$2:$B$180,"=GDP",'MoodysData(Raw)'!$D$2:$D$180,"="&'Implied Productivity Ratios'!$C9)/SUMIFS('MoodysData(Raw)'!J$2:J$180,'MoodysData(Raw)'!$B$2:$B$180,"=EMP",'MoodysData(Raw)'!$D$2:$D$180,"="&'Implied Productivity Ratios'!$C9) -> 945.42756 | H9: =SUMIFS('MoodysData(Raw)'!K$2:K$180,'MoodysData(Raw)'!$B$2:$B$180,"=GDP",'MoodysData(Raw)'!$D$2:$D$180,"="&'Implied Productivity Ratios'!$C9)/SUMIFS('MoodysData(Raw)'!K$2:K$180,'MoodysData(Raw)'!$B$2:$B$180,"=EMP",'MoodysData(Raw)'!$D$2:$D$180,"="&'Implied Productivity Ratios'!$C9) -> 984.43786 | I9: =SUMIFS('MoodysData(Raw)'!L$2:L$180,'MoodysData(Raw)'!$B$2:$B$180,"=GDP",'MoodysData(Raw)'!$D$2:$D$180,"="&'Implied Productivity Ratios'!$C9)/SUMIFS('MoodysData(Raw)'!L$2:L$180,'MoodysData(Raw)'!$B$2:$B$180,"=EMP",'MoodysData(Raw)'!$D$2:$D$180,"="&'Implied Productivity Ratios'!$C9) -> 912.41619 | J9: =SUMIFS('MoodysData(Raw)'!M$2:M$180,'MoodysData(Raw)'!$B$2:$B$180,"=GDP",'MoodysData(Raw)'!$D$2:$D$180,"="&'Implied Productivity Ratios'!$C9)/SUMIFS('MoodysData(Raw)'!M$2:M$180,'MoodysData(Raw)'!$B$2:$B$180,"=EMP",'MoodysData(Raw)'!$D$2:$D$180,"="&'Implied Productivity Ratios'!$C9) -> 1047.4973 | K9: =SUMIFS('MoodysData(Raw)'!N$2:N$180,'MoodysData(Raw)'!$B$2:$B$180,"=GDP",'MoodysData(Raw)'!$D$2:$D$180,"="&'Implied Productivity Ratios'!$C9)/SUMIFS('MoodysData(Raw)'!N$2:N$180,'MoodysData(Raw)'!$B$2:$B$180,"=EMP",'MoodysData(Raw)'!$D$2:$D$180,"="&'Implied Productivity Ratios'!$C9) -> 1091.3132 | L9: =SUMIFS('MoodysData(Raw)'!O$2:O$180,'MoodysData(Raw)'!$B$2:$B$180,"=GDP",'MoodysData(Raw)'!$D$2:$D$180,"="&'Implied Productivity Ratios'!$C9)/SUMIFS('MoodysData(Raw)'!O$2:O$180,'MoodysData(Raw)'!$B$2:$B$180,"=EMP",'MoodysData(Raw)'!$D$2:$D$180,"="&'Implied Productivity Ratios'!$C9) -> 1109.1117 | ... BC9: =SUMIFS('MoodysData(Raw)'!BF$2:BF$180,'MoodysData(Raw)'!$B$2:$B$180,"=GDP",'MoodysData(Raw)'!$D$2:$D$180,"="&'Implied Productivity Ratios'!$C9)/SUMIFS('MoodysData(Raw)'!BF$2:BF$180,'MoodysData(Raw)'!$B$2:$B$180,"=EMP",'MoodysData(Raw)'!$D$2:$D$180,"="&'Implied Productivity Ratios'!$C9) -> 2048.3807 | BD9: =BC9+($BC9-$AX9)/5 -> 2077.2536 | BE9: =BD9+($BC9-$AX9)/5 -> 2106.1264 | BF9: =BE9+($BC9-$AX9)/5 -> 2134.9992 | BG9: =BF9+($BC9-$AX9)/5 -> 2163.8721 | BH9: =BG9+($BC9-$AX9)/5 -> 2192.7449
C10: 236 | D10: Construction of buildings | E10: =SUMIFS('MoodysData(Raw)'!H$2:H$180,'MoodysData(Raw)'!$B$2:$B$180,"=GDP",'MoodysData(Raw)'!$D$2:$D$180,"="&'Implied Productivity Ratios'!$C10)/SUMIFS('MoodysData(Raw)'!H$2:H$180,'MoodysData(Raw)'!$B$2:$B$180,"=EMP",'MoodysData(Raw)'!$D$2:$D$180,"="&'Implied Productivity Ratios'!$C10) -> 143.00672 | F10: =SUMIFS('MoodysData(Raw)'!I$2:I$180,'MoodysData(Raw)'!$B$2:$B$180,"=GDP",'MoodysData(Raw)'!$D$2:$D$180,"="&'Implied Productivity Ratios'!$C10)/SUMIFS('MoodysData(Raw)'!I$2:I$180,'MoodysData(Raw)'!$B$2:$B$180,"=EMP",'MoodysData(Raw)'!$D$2:$D$180,"="&'Implied Productivity Ratios'!$C10) -> 133.86311 | G10: =SUMIFS('MoodysData(Raw)'!J$2:J$180,'MoodysData(Raw)'!$B$2:$B$180,"=GDP",'MoodysData(Raw)'!$D$2:$D$180,"="&'Implied Productivity Ratios'!$C10)/SUMIFS('MoodysData(Raw)'!J$2:J$180,'MoodysData(Raw)'!$B$2:$B$180,"=EMP",'MoodysData(Raw)'!$D$2:$D$180,"="&'Implied Productivity Ratios'!$C10) -> 129.40465 | H10: =SUMIFS('MoodysData(Raw)'!K$2:K$180,'MoodysData(Raw)'!$B$2:$B$180,"=GDP",'MoodysData(Raw)'!$D$2:$D$180,"="&'Implied Productivity Ratios'!$C10)/SUMIFS('MoodysData(Raw)'!K$2:K$180,'MoodysData(Raw)'!$B$2:$B$180,"=EMP",'MoodysData(Raw)'!$D$2:$D$180,"="&'Implied Productivity Ratios'!$C10) -> 122.85929 | I10: =SUMIFS('MoodysData(Raw)'!L$2:L$180,'MoodysData(Raw)'!$B$2:$B$180,"=GDP",'MoodysData(Raw)'!$D$2:$D$180,"="&'Implied Productivity Ratios'!$C10)/SUMIFS('MoodysData(Raw)'!L$2:L$180,'MoodysData(Raw)'!$B$2:$B$180,"=EMP",'MoodysData(Raw)'!$D$2:$D$180,"="&'Implied Productivity Ratios'!$C10) -> 125.94077 | J10: =SUMIFS('MoodysData(Raw)'!M$2:M$180,'MoodysData(Raw)'!$B$2:$B$180,"=GDP",'MoodysData(Raw)'!$D$2:$D$180,"="&'Implied Productivity Ratios'!$C10)/SUMIFS('MoodysData(Raw)'!M$2:M$180,'MoodysData(Raw)'!$B$2:$B$180,"=EMP",'MoodysData(Raw)'!$D$2:$D$180,"="&'Implied Productivity Ratios'!$C10) -> 129.14802 | K10: =SUMIFS('MoodysData(Raw)'!N$2:N$180,'MoodysData(Raw)'!$B$2:$B$180,"=GDP",'MoodysData(Raw)'!$D$2:$D$180,"="&'Implied Productivity Ratios'!$C10)/SUMIFS('MoodysData(Raw)'!N$2:N$180,'MoodysData(Raw)'!$B$2:$B$180,"=EMP",'MoodysData(Raw)'!$D$2:$D$180,"="&'Implied Productivity Ratios'!$C10) -> 126.98019 | L10: =SUMIFS('MoodysData(Raw)'!O$2:O$180,'MoodysData(Raw)'!$B$2:$B$180,"=GDP",'MoodysData(Raw)'!$D$2:$D$180,"="&'Implied Productivity Ratios'!$C10)/SUMIFS('MoodysData(Raw)'!O$2:O$180,'MoodysData(Raw)'!$B$2:$B$180,"=EMP",'MoodysData(Raw)'!$D$2:$D$180,"="&'Implied Productivity Ratios'!$C10) -> 128.45023 | ... BC10: =SUMIFS('MoodysData(Raw)'!BF$2:BF$180,'MoodysData(Raw)'!$B$2:$B$180,"=GDP",'MoodysData(Raw)'!$D$2:$D$180,"="&'Implied Productivity Ratios'!$C10)/SUMIFS('MoodysData(Raw)'!BF$2:BF$180,'MoodysData(Raw)'!$B$2:$B$180,"=EMP",'MoodysData(Raw)'!$D$2:$D$180,"="&'Implied Productivity Ratios'!$C10) -> 149.03412 | BD10: =BC10+($BC10-$AX10)/5 -> 149.77197 | BE10: =BD10+($BC10-$AX10)/5 -> 150.50982 | BF10: =BE10+($BC10-$AX10)/5 -> 151.24767 | BG10: =BF10+($BC10-$AX10)/5 -> 151.98552 | BH10: =BG10+($BC10-$AX10)/5 -> 152.72336
